Workbook

Sheet LISTRIK 2026
A1: DATA LISTRIK TENANT PENTACITY
A4: UPDATE 28 APRIL 2026
A5: NO. | B5: NAMA TENANT | C5: LANTAI UNIT | E5: DAYA LISTRIK | F5: JENIS KWH | G5: TYPE KWH | H5: NO KWH | I5: 46020 | J5: 46051 | K5: 46079 | L5: 46111 | M5: 46140 | N5: ON/OFF | O5: KETERANGAN | P5: TTD & STEMPEL
N6: STAND AWAL - STAND AKHIR
A7: 1 | B7: HYPERMART PUTR (DOUBLE TARIF) (TOTAL) | C7: LG | D7: ANCHOR E | E7: 3 FASE 400 A | F7: SCHNEIDER | H7: 1015163133 | I7: 9292354.6 | J7: 9355186.6 | K7: 9412683.8 | L7: 9478742.6 | M7: 9539749.7
B8: HYPERMART PUTR TARIF 1 (LWBP) | I8: 7007089.3 | J8: 7055092.7 | K8: 7099052.2 | L8: 7149405.3 | M8: 7196164.9
B9: HYPERMART PUTR TARIF 2 (WBP) | I9: 2284536.4 | J9: 2299364.6 | K9: 2312902.3 | L9: 2328606.6 | M9: 2342854
B10: HYPERMART GENSET PUTR | F10: SOCOMEC | G10: E43 | H10: 17282010063 | I10: 3324 | J10: 3382 | K10: 3382 | L10: 3383 | M10: 4010
B11: HYPERMART AHU (AC) (DOUBLE TARIF) (TOTAL) | E11: 3 FASE 600 A | F11: SCHNEIDER | H11: 1915184007 | I11: 1897056.3 | J11: 1920016.6 | K11: 1935461.8 | L11: 1953692.4 | M11: 1975834.6
B12: HYPERMART AHU (AC) TARIF 1 (LWBP) | I12: 1158893.6 | J12: 1173833.3 | K12: 1183802.2 | L12: 1195761 | M12: 1210089.2
B13: HYPERMART AHU (AC) TARIF 2 (WBP) | I13: 738161.6 | J13: 746182.3 | K13: 751658.8 | L13: 757929.9 | M13: 765744.1
B14: HYPERMART GENSET AHU (AC) | F14: SOCOMEC | G14: E40 | H14: 18072010604 | I14: 671 | J14: 671 | K14: 672 | L14: 672 | M14: 672
B15: LOGO WALLSIGN HYPERMART (DOUBLE TARIF) (TOTAL) | E15: 1 FASE 10 A | F15: SOCOMEC | G15: E10 | H15: 13132010735 | I15: 3975.5 | J15: 4018.8 | K15: 4059.6 | L15: 4105.7 | M15: 4146.4
B16: LOGO WALLSIGN HYPERMART TARIF 1 (LWBP) | G16: E10 | I16: 1136.8 | J16: 1136.9 | K16: 1136.9 | L16: 1136.9 | M16: 1136.9
B17: LOGO WALLSIGN HYPERMART TARIF 2 (WBP) | G17: E10 | I17: 2838.7 | J17: 2882 | K17: 2922.7 | L17: 2968.9 | M17: 3009.6
B18: LOGO GENSET WALLSIGN HYPERMART | G18: E10 | H18: 15342010953 | I18: 37.7 | J18: 37 | K18: 37 | L18: 37 | M18: 37.5
A19: 2 | B19: NEW MINISO | C19: LG | D19: 01 - 03B | E19: 3 FASE 50 A | F19: SOCOMEC | G19: E30 | H19: 13262012698 | I19: 286318 | J19: 294189 | K19: 302448 | L19: 312443 | M19: 321442
A20: 3 | B20: IMPERIAL KITCHEN | C20: LG | D20: 6 | E20: 3 FASE 80 A | F20: SOCOMEC | G20: E20 | H20: 17202012200 | I20: 303787 | J20: 311721 | K20: 318447 | L20: 326256 | M20: 332897
A21: 4 | B21: BAKOEL BAMBOE | C21: LG | D21: 06 A | E21: 3 FASE 40 A | F21: SOCOMEC | G21: E20 | I21: 60586 | J21: 65115 | K21: 69215 | L21: 74083 | M21: 78255
B22: GUDANG BAKOEL BAMBOE | C22: P3 | D22: PARKIRAN | E22: 3 FASE 40 A | F22: SOCOMEC | G22: E20 | I22: 65326.9 | J22: 69455.6 | K22: 73421.2 | L22: 78825.2 | M22: 83352.6
A23: 5 | B23: YOSHINOYA | C23: LG | D23: 27 | E23: 3 FASE 100 A | F23: SOCOMEC | G23: E40 | H23: 14402010813 | I23: 7684.9 | J23: 15470.8 | K23: 23198.4 | L23: 31840.8 | M23: 39189.1
A24: 6 | B24: GURIH NUSANTARA | C24: LG | D24: 24 | E24: 3 FASE 20 A | F24: SOCOMEC | G24: E20 | I24: 61319 | J24: 63107 | K24: 64783 | L24: 66755 | M24: 68580
A25: 7 | B25: BONCAFE | C25: LG | D25: 23, 23A - 25 | E25: 3 FASE 20 A | F25: SOCOMEC | G25: E20 | H25: 0722206098 | I25: 211392.9 | J25: 219890.5 | K25: 227668.4 | L25: 236792.7 | M25: 236792.7
B26: BONCAFE | C26: LG | D26: 23, 23A - 25 | E26: 3 FASE 20 A | F26: SCHNEIDER | L26: 0.6 | M26: 2580.7 | N26: ON 18 APRIL 2026 STAND AWAL 0.6 KWH
A27: 8 | B27: LUCA | C27: LG | D27: ISLAND | F27: SCHNEIDER | H27: 214152054 | I27: 36197 | J27: 37124.1 | K27: 37885.3 | L27: 38811 | M27: 39659.9
B28: JUSCRACK | I28: 172938 | J28: 173210 | K28: 173452 | L28: 173673 | M28: 174030
A29: 9 | B29: DCREPES | C29: LG | I29: 133674 | J29: 134831 | K29: 135850 | L29: 137072 | M29: 138151
B30: GUDANG D'CREPES | I30: 4108.7 | J30: 4725.1 | K30: 5278.7 | L30: 5931.3 | M30: 6494.1
A31: 10 | B31: TAWAN | C31: LG | D31: 07 | E31: 3 FASE 50 A | F31: SOCOMEC | G31: E30 | H31: 13262012720 | I31: 327327 | J31: 330908 | K31: 334006 | L31: 337898 | M31: 341081
B32: GUDANG TAWAN | C32: P4 | E32: 1 FASE 16 A | F32: SOCOMEC | G32: AM10 | H32: IEC 62053-21 | I32: 14570.5 | J32: 15225.1 | K32: 15819.9 | L32: 16495.7 | M32: 17095.3
A33: 11 | B33: PEPPER LUNCH | C33: LG | D33: 08 | E33: 3 FASE 6 A | F33: SCHNEIDER | H33: 1025084099 | I33: 18810.7 | J33: 26413.9 | K33: 32788 | L33: 40797.1 | M33: 47527.5
B34: GUDANG PEPPER LUNCH | C34: P1 | D34: GUDANG NO. 1 | E34: 1 FASE 16 A | F34: SOCOMEC | G34: AM10 | H34: 11123311334 | I34: 39684.9 | J34: 40603.4 | K34: 41419.6 | L34: 42358.6 | M34: 43186.7
A35: 12 | B35: RAMEN 01 | C35: LG | D35: 9 | E35: 3 FASE 32 A | F35: SOCOMEC | G35: E20 | I35: 142861 | J35: 145485 | K35: 147898 | L35: 150632 | M35: 153068
A36: 13 | B36: ICHIBAN SUSHI | C36: LG | D36: 10 | E36: 3 FASE 32 A | F36: SOCOMEC | G36: E20 | H36: 17272011265 | I36: 217202 | J36: 220171 | K36: 222854 | L36: 226041 | M36: 228995
A37: 14 | B37: ROYAL K BBQ | C37: LG | D37: 11 | E37: 3 FASE 25 A | F37: SCHNEIDER | H37: 0214496105 | I37: 81533 | J37: 82885.3 | K37: 84078.3 | L37: 85428.1 | M37: 86702.3
A38: 15 | B38: SOLARIA | C38: LG | D38: 12 - 12 A | E38: 3 FASE 40 A | F38: SOCOMEC | G38: E21 | H38: 13152011170 | I38: 348190 | J38: 353678 | K38: 358685 | L38: 364723 | M38: 369967
A39: 16 | B39: DAPUR SOLO | C39: LG | D39: 13 | E39: 3 FASE 32 A | F39: SCHNEIDER | H39: 0219076016 | I39: 94969.9 | J39: 98370.8 | K39: 101394.3 | L39: 104702.3 | M39: 107570.5
B40: GUDANG DAPUR SOLO | I40: 171727 | J40: 172815 | K40: 173716 | L40: 175040 | M40: 176022
A41: 17 | B41: BABAKU | C41: LG | D41: 16 | E41: 3 FASE 20 A | F41: SOCOMEC | G41: E20 | I41: 64404 | J41: 65815 | K41: 67054 | L41: 68487 | M41: 69733
A42: 18 | B42: KFC | C42: LG | D42: 17 - 19 | E42: 3 FASE 100 A | F42: SCHNEIDER | H42: 717441052 | I42: 428969.1 | J42: 431216 | K42: 433148.4 | L42: 435190.1 | M42: 437211.4
...

Sheet REKAP LISTRIK 2026
A1: REKAP DATA LISTRIK TENANT PENTACITY
A4: ='LISTRIK 2026'!A4 -> UPDATE 28 APRIL 2026
A5: NO. | B5: NAMA TENANT | C5: LANTAI UNIT | E5: DAYA LISTRIK | F5: JENIS KWH | G5: TYPE KWH | H5: NO KWH | I5: 46051 | J5: 46079 | K5: 46111 | L5: 46140 | M5: KETERANGAN
A7: 1 | B7: HYPERMART PUTR (DOUBLE TARIF) (TOTAL) | C7: LG | D7: ANCHOR E | E7: 3 FASE 400 A | F7: SCHNEIDER | H7: 1015163133 | I7: ='LISTRIK 2026'!J7-'LISTRIK 2026'!I7 -> 62832 | J7: ='LISTRIK 2026'!K7-'LISTRIK 2026'!J7 -> 57497.2 | K7: ='LISTRIK 2026'!L7-'LISTRIK 2026'!K7 -> 66058.8 | L7: ='LISTRIK 2026'!M7-'LISTRIK 2026'!L7 -> 61007.1
B8: HYPERMART PUTR TARIF 1 (LWBP) | I8: ='LISTRIK 2026'!J8-'LISTRIK 2026'!I8 -> 48003.4 | J8: ='LISTRIK 2026'!K8-'LISTRIK 2026'!J8 -> 43959.5 | K8: ='LISTRIK 2026'!L8-'LISTRIK 2026'!K8 -> 50353.1 | L8: ='LISTRIK 2026'!M8-'LISTRIK 2026'!L8 -> 46759.6
B9: HYPERMART PUTR TARIF 2 (WBP) | I9: ='LISTRIK 2026'!J9-'LISTRIK 2026'!I9 -> 14828.2 | J9: ='LISTRIK 2026'!K9-'LISTRIK 2026'!J9 -> 13537.7 | K9: ='LISTRIK 2026'!L9-'LISTRIK 2026'!K9 -> 15704.3 | L9: ='LISTRIK 2026'!M9-'LISTRIK 2026'!L9 -> 14247.4
B10: HYPERMART GENSET PUTR | F10: SOCOMEC | G10: E43 | H10: 17282010063 | I10: ='LISTRIK 2026'!J10-'LISTRIK 2026'!I10 -> 58 | J10: ='LISTRIK 2026'!K10-'LISTRIK 2026'!J10 -> 0 | K10: ='LISTRIK 2026'!L10-'LISTRIK 2026'!K10 -> 1 | L10: ='LISTRIK 2026'!M10-'LISTRIK 2026'!L10 -> 627
B11: HYPERMART AHU (AC) (DOUBLE TARIF) (TOTAL) | E11: 3 FASE 600 A | F11: SCHNEIDER | H11: 1915184007 | I11: ='LISTRIK 2026'!J11-'LISTRIK 2026'!I11 -> 22960.3 | J11: ='LISTRIK 2026'!K11-'LISTRIK 2026'!J11 -> 15445.2 | K11: ='LISTRIK 2026'!L11-'LISTRIK 2026'!K11 -> 18230.6 | L11: ='LISTRIK 2026'!M11-'LISTRIK 2026'!L11 -> 22142.2
B12: HYPERMART AHU (AC) TARIF 1 (LWBP) | I12: ='LISTRIK 2026'!J12-'LISTRIK 2026'!I12 -> 14939.7 | J12: ='LISTRIK 2026'!K12-'LISTRIK 2026'!J12 -> 9968.9 | K12: ='LISTRIK 2026'!L12-'LISTRIK 2026'!K12 -> 11958.8 | L12: ='LISTRIK 2026'!M12-'LISTRIK 2026'!L12 -> 14328.2
B13: HYPERMART AHU (AC) TARIF 2 (WBP) | I13: ='LISTRIK 2026'!J13-'LISTRIK 2026'!I13 -> 8020.7 | J13: ='LISTRIK 2026'!K13-'LISTRIK 2026'!J13 -> 5476.5 | K13: ='LISTRIK 2026'!L13-'LISTRIK 2026'!K13 -> 6271.1 | L13: ='LISTRIK 2026'!M13-'LISTRIK 2026'!L13 -> 7814.2
B14: HYPERMART GENSET AHU (AC) | F14: SOCOMEC | G14: E40 | H14: 18072010604 | I14: ='LISTRIK 2026'!J14-'LISTRIK 2026'!I14 -> 0 | J14: ='LISTRIK 2026'!K14-'LISTRIK 2026'!J14 -> 1 | K14: ='LISTRIK 2026'!L14-'LISTRIK 2026'!K14 -> 0 | L14: ='LISTRIK 2026'!M14-'LISTRIK 2026'!L14 -> 0
B15: LOGO WALLSIGN HYPERMART (DOUBLE TARIF) (TOTAL) | E15: 1 FASE 10 A | F15: SOCOMEC | G15: E10 | H15: 13132010735 | I15: ='LISTRIK 2026'!J15-'LISTRIK 2026'!I15 -> 43.3 | J15: ='LISTRIK 2026'!K15-'LISTRIK 2026'!J15 -> 40.8 | K15: ='LISTRIK 2026'!L15-'LISTRIK 2026'!K15 -> 46.1 | L15: ='LISTRIK 2026'!M15-'LISTRIK 2026'!L15 -> 40.7
B16: LOGO WALLSIGN HYPERMART TARIF 1 (LWBP) | G16: E10 | I16: ='LISTRIK 2026'!J16-'LISTRIK 2026'!I16 -> 0.1 | J16: ='LISTRIK 2026'!K16-'LISTRIK 2026'!J16 -> 0 | K16: ='LISTRIK 2026'!L16-'LISTRIK 2026'!K16 -> 0 | L16: ='LISTRIK 2026'!M16-'LISTRIK 2026'!L16 -> 0
B17: LOGO WALLSIGN HYPERMART TARIF 2 (WBP) | G17: E10 | I17: ='LISTRIK 2026'!J17-'LISTRIK 2026'!I17 -> 43.3 | J17: ='LISTRIK 2026'!K17-'LISTRIK 2026'!J17 -> 40.7 | K17: ='LISTRIK 2026'!L17-'LISTRIK 2026'!K17 -> 46.2 | L17: ='LISTRIK 2026'!M17-'LISTRIK 2026'!L17 -> 40.7
B18: LOGO GENSET WALLSIGN HYPERMART | G18: E10 | H18: 15342010953 | I18: ='LISTRIK 2026'!J18-'LISTRIK 2026'!I18 -> -0.7 | J18: ='LISTRIK 2026'!K18-'LISTRIK 2026'!J18 -> 0 | K18: ='LISTRIK 2026'!L18-'LISTRIK 2026'!K18 -> 0 | L18: ='LISTRIK 2026'!M18-'LISTRIK 2026'!L18 -> 0.5
A19: 2 | B19: NEW MINISO | C19: LG | D19: 01 - 03B | E19: 3 FASE 50 A | F19: SOCOMEC | G19: E30 | H19: 13262012698 | I19: ='LISTRIK 2026'!J19-'LISTRIK 2026'!I19 -> 7871 | J19: ='LISTRIK 2026'!K19-'LISTRIK 2026'!J19 -> 8259 | K19: ='LISTRIK 2026'!L19-'LISTRIK 2026'!K19 -> 9995 | L19: ='LISTRIK 2026'!M19-'LISTRIK 2026'!L19 -> 8999
A20: 3 | B20: IMPERIAL KITCHEN | C20: LG | D20: 6 | E20: 3 FASE 80 A | F20: SOCOMEC | G20: E20 | H20: 17202012200 | I20: ='LISTRIK 2026'!J20-'LISTRIK 2026'!I20 -> 7934 | J20: ='LISTRIK 2026'!K20-'LISTRIK 2026'!J20 -> 6726 | K20: ='LISTRIK 2026'!L20-'LISTRIK 2026'!K20 -> 7809 | L20: ='LISTRIK 2026'!M20-'LISTRIK 2026'!L20 -> 6641
A21: 4 | B21: BAKOEL BAMBOE | C21: LG | D21: 06 A | E21: 3 FASE 40 A | F21: SOCOMEC | G21: E20 | I21: ='LISTRIK 2026'!J21-'LISTRIK 2026'!I21 -> 4529 | J21: ='LISTRIK 2026'!K21-'LISTRIK 2026'!J21 -> 4100 | K21: ='LISTRIK 2026'!L21-'LISTRIK 2026'!K21 -> 4868 | L21: ='LISTRIK 2026'!M21-'LISTRIK 2026'!L21 -> 4172
B22: GUDANG BAKOEL BAMBOE | C22: P3 | D22: PARKIRAN | E22: 3 FASE 40 A | F22: SOCOMEC | G22: E20 | I22: ='LISTRIK 2026'!J22-'LISTRIK 2026'!I22 -> 4128.7 | J22: ='LISTRIK 2026'!K22-'LISTRIK 2026'!J22 -> 3965.6 | K22: ='LISTRIK 2026'!L22-'LISTRIK 2026'!K22 -> 5404 | L22: ='LISTRIK 2026'!M22-'LISTRIK 2026'!L22 -> 4527.4
A23: 5 | B23: YOSHINOYA | C23: LG | D23: 27 | E23: 3 FASE 100 A | F23: SOCOMEC | G23: E40 | H23: 14402010813 | I23: ='LISTRIK 2026'!J23-'LISTRIK 2026'!I23 -> 7785.9 | J23: ='LISTRIK 2026'!K23-'LISTRIK 2026'!J23 -> 7727.6 | K23: ='LISTRIK 2026'!L23-'LISTRIK 2026'!K23 -> 8642.4 | L23: ='LISTRIK 2026'!M23-'LISTRIK 2026'!L23 -> 7348.3
A24: 6 | B24: GURIH NUSANTARA | C24: LG | D24: 24 | E24: 3 FASE 20 A | F24: SOCOMEC | G24: E20 | I24: ='LISTRIK 2026'!J24-'LISTRIK 2026'!I24 -> 1788 | J24: ='LISTRIK 2026'!K24-'LISTRIK 2026'!J24 -> 1676 | K24: ='LISTRIK 2026'!L24-'LISTRIK 2026'!K24 -> 1972 | L24: ='LISTRIK 2026'!M24-'LISTRIK 2026'!L24 -> 1825
A25: 7 | B25: BONCAFE | C25: LG | D25: 23, 23A - 25 | E25: 3 FASE 125 A | F25: SOCOMEC | G25: E20 | H25: 0722206098 | I25: ='LISTRIK 2026'!J25-'LISTRIK 2026'!I25 -> 8497.6 | J25: ='LISTRIK 2026'!K25-'LISTRIK 2026'!J25 -> 7777.9 | K25: ='LISTRIK 2026'!L25-'LISTRIK 2026'!K25 -> 9124.3 | L25: ='LISTRIK 2026'!M25-'LISTRIK 2026'!L25 -> 0
B26: BONCAFE | C26: LG | D26: 23, 23A - 25 | K26: ='LISTRIK 2026'!L26-'LISTRIK 2026'!K26 -> 0.6 | L26: ='LISTRIK 2026'!M26-'LISTRIK 2026'!L26 -> 2580.1
A27: 8 | B27: LUCA | C27: LG | D27: ISLAND | F27: SCHNEIDER | H27: 214152054 | I27: ='LISTRIK 2026'!J27-'LISTRIK 2026'!I27 -> 927.1 | J27: ='LISTRIK 2026'!K27-'LISTRIK 2026'!J27 -> 761.2 | K27: ='LISTRIK 2026'!L27-'LISTRIK 2026'!K27 -> 925.7 | L27: ='LISTRIK 2026'!M27-'LISTRIK 2026'!L27 -> 848.9
B28: JUSCRACK | I28: ='LISTRIK 2026'!J28-'LISTRIK 2026'!I28 -> 272 | J28: ='LISTRIK 2026'!K28-'LISTRIK 2026'!J28 -> 242 | K28: ='LISTRIK 2026'!L28-'LISTRIK 2026'!K28 -> 221 | L28: ='LISTRIK 2026'!M28-'LISTRIK 2026'!L28 -> 357
A29: 9 | B29: DCREPES | C29: LG | I29: ='LISTRIK 2026'!J29-'LISTRIK 2026'!I29 -> 1157 | J29: ='LISTRIK 2026'!K29-'LISTRIK 2026'!J29 -> 1019 | K29: ='LISTRIK 2026'!L29-'LISTRIK 2026'!K29 -> 1222 | L29: ='LISTRIK 2026'!M29-'LISTRIK 2026'!L29 -> 1079
B30: GUDANG D'CREPES | I30: ='LISTRIK 2026'!J30-'LISTRIK 2026'!I30 -> 616.4 | J30: ='LISTRIK 2026'!K30-'LISTRIK 2026'!J30 -> 553.6 | K30: ='LISTRIK 2026'!L30-'LISTRIK 2026'!K30 -> 652.6 | L30: ='LISTRIK 2026'!M30-'LISTRIK 2026'!L30 -> 562.8
A31: 10 | B31: TAWAN | C31: LG | D31: 07 | E31: 3 FASE 50 A | F31: SOCOMEC | G31: E30 | H31: 13262012720 | I31: ='LISTRIK 2026'!J31-'LISTRIK 2026'!I31 -> 3581 | J31: ='LISTRIK 2026'!K31-'LISTRIK 2026'!J31 -> 3098 | K31: ='LISTRIK 2026'!L31-'LISTRIK 2026'!K31 -> 3892 | L31: ='LISTRIK 2026'!M31-'LISTRIK 2026'!L31 -> 3183
B32: GUDANG TAWAN | C32: P4 | E32: 1 FASE 16 A | F32: SOCOMEC | G32: AM10 | H32: IEC 62053-21 | I32: ='LISTRIK 2026'!J32-'LISTRIK 2026'!I32 -> 654.6 | J32: ='LISTRIK 2026'!K32-'LISTRIK 2026'!J32 -> 594.8 | K32: ='LISTRIK 2026'!L32-'LISTRIK 2026'!K32 -> 675.8 | L32: ='LISTRIK 2026'!M32-'LISTRIK 2026'!L32 -> 599.6
A33: 11 | B33: PEPPER LUNCH | C33: LG | D33: 08 | E33: 3 FASE 6 A | F33: SCHNEIDER | H33: 1025084099 | I33: ='LISTRIK 2026'!J33-'LISTRIK 2026'!I33 -> 7603.2 | J33: ='LISTRIK 2026'!K33-'LISTRIK 2026'!J33 -> 6374.1 | K33: ='LISTRIK 2026'!L33-'LISTRIK 2026'!K33 -> 8009.1 | L33: ='LISTRIK 2026'!M33-'LISTRIK 2026'!L33 -> 6730.4
B34: GUDANG PEPPER LUNCH | C34: P1 | D34: GUDANG NO. 1 | E34: 1 FASE 16 A | F34: SOCOMEC | G34: AM10 | H34: 11123311334 | I34: ='LISTRIK 2026'!J34-'LISTRIK 2026'!I34 -> 918.5 | J34: ='LISTRIK 2026'!K34-'LISTRIK 2026'!J34 -> 816.2 | K34: ='LISTRIK 2026'!L34-'LISTRIK 2026'!K34 -> 939 | L34: ='LISTRIK 2026'!M34-'LISTRIK 2026'!L34 -> 828.1
A35: 12 | B35: RAMEN 01 | C35: LG | D35: 9 | E35: 3 FASE 32 A | F35: SOCOMEC | G35: E20 | I35: ='LISTRIK 2026'!J35-'LISTRIK 2026'!I35 -> 2624 | J35: ='LISTRIK 2026'!K35-'LISTRIK 2026'!J35 -> 2413 | K35: ='LISTRIK 2026'!L35-'LISTRIK 2026'!K35 -> 2734 | L35: ='LISTRIK 2026'!M35-'LISTRIK 2026'!L35 -> 2436
A36: 13 | B36: ICHIBAN SUSHI | C36: LG | D36: 10 | E36: 3 FASE 32 A | F36: SOCOMEC | G36: E20 | H36: 17272011265 | I36: ='LISTRIK 2026'!J36-'LISTRIK 2026'!I36 -> 2969 | J36: ='LISTRIK 2026'!K36-'LISTRIK 2026'!J36 -> 2683 | K36: ='LISTRIK 2026'!L36-'LISTRIK 2026'!K36 -> 3187 | L36: ='LISTRIK 2026'!M36-'LISTRIK 2026'!L36 -> 2954
A37: 14 | B37: ROYAL K BBQ | C37: LG | D37: 11 | E37: 3 FASE 25 A | F37: SCHNEIDER | H37: 0214496105 | I37: ='LISTRIK 2026'!J37-'LISTRIK 2026'!I37 -> 1352.3 | J37: ='LISTRIK 2026'!K37-'LISTRIK 2026'!J37 -> 1193 | K37: ='LISTRIK 2026'!L37-'LISTRIK 2026'!K37 -> 1349.8 | L37: ='LISTRIK 2026'!M37-'LISTRIK 2026'!L37 -> 1274.2
A38: 15 | B38: SOLARIA | C38: LG | D38: 12 - 12 A | E38: 3 FASE 40 A | F38: SOCOMEC | G38: E21 | H38: 13152011170 | I38: ='LISTRIK 2026'!J38-'LISTRIK 2026'!I38 -> 5488 | J38: ='LISTRIK 2026'!K38-'LISTRIK 2026'!J38 -> 5007 | K38: ='LISTRIK 2026'!L38-'LISTRIK 2026'!K38 -> 6038 | L38: ='LISTRIK 2026'!M38-'LISTRIK 2026'!L38 -> 5244
A39: 16 | B39: DAPUR SOLO | C39: LG | D39: 13 | E39: 3 FASE 32 A | F39: SCHNEIDER | H39: 0219076016 | I39: ='LISTRIK 2026'!J39-'LISTRIK 2026'!I39 -> 3400.9 | J39: ='LISTRIK 2026'!K39-'LISTRIK 2026'!J39 -> 3023.5 | K39: ='LISTRIK 2026'!L39-'LISTRIK 2026'!K39 -> 3308 | L39: ='LISTRIK 2026'!M39-'LISTRIK 2026'!L39 -> 2868.2
B40: GUDANG DAPUR SOLO | I40: ='LISTRIK 2026'!J40-'LISTRIK 2026'!I40 -> 1088 | J40: ='LISTRIK 2026'!K40-'LISTRIK 2026'!J40 -> 901 | K40: ='LISTRIK 2026'!L40-'LISTRIK 2026'!K40 -> 1324 | L40: ='LISTRIK 2026'!M40-'LISTRIK 2026'!L40 -> 982
A41: 17 | B41: BABAKU | C41: LG | D41: 16 | E41: 3 FASE 20 A | F41: SOCOMEC | G41: E20 | I41: ='LISTRIK 2026'!J41-'LISTRIK 2026'!I41 -> 1411 | J41: ='LISTRIK 2026'!K41-'LISTRIK 2026'!J41 -> 1239 | K41: ='LISTRIK 2026'!L41-'LISTRIK 2026'!K41 -> 1433 | L41: ='LISTRIK 2026'!M41-'LISTRIK 2026'!L41 -> 1246
A42: 18 | B42: KFC | C42: LG | D42: 17 - 19 | E42: 3 FASE 100 A | F42: SCHNEIDER | H42: 717441052 | I42: ='LISTRIK 2026'!J42-'LISTRIK 2026'!I42 -> 2246.9 | J42: ='LISTRIK 2026'!K42-'LISTRIK 2026'!J42 -> 1932.4 | K42: ='LISTRIK 2026'!L42-'LISTRIK 2026'!K42 -> 2041.7 | L42: ='LISTRIK 2026'!M42-'LISTRIK 2026'!L42 -> 2021.3
B43: KFC LOGO (WALLSIGN) | C43: P5 | D43: P5 | E43: 1 FASE 10 A | F43: SOCOMEC | G43: AM10 | H43: 11183313009 | I43: ='LISTRIK 2026'!J43-'LISTRIK 2026'!I43 -> 11.5 | J43: ='LISTRIK 2026'!K43-'LISTRIK 2026'!J43 -> 10.7 | K43: ='LISTRIK 2026'!L43-'LISTRIK 2026'!K43 -> 12.1 | L43: ='LISTRIK 2026'!M43-'LISTRIK 2026'!L43 -> 11
...
